<?xml version="1.0"?>
<robot name="mybot">

  <link name="base_footprint" />

  <joint name="base_joint" type="fixed">
    <parent link="base_footprint" />
    <child link="base_link" />
    <origin rpy="0 0 0" xyz="0 0 0" />
  </joint>

  <link name="base_link">
    <inertial>
      <origin xyz="0 0 0" rpy="0 0 0" />
      <mass value="0.1" />
      <inertia ixx="0.1" ixy="0" ixz="0" iyy="0.1" iyz="0" izz="0.1" />
    </inertial>

    <visual>
      <geometry>
        <box size="0.25 0.16 0.05" />
      </geometry>
      <origin rpy="0 0 0" xyz="0 0 0" />
      <material name="blue">
        <color rgba="0 0 0.8 1" />
      </material>
    </visual>

    <collision>
      <origin xyz="0 0 0" rpy="0 0 0" />
      <geometry>
        <box size="0.25 0.16 0.05" />
      </geometry>
    </collision>

  </link>

  <link name="right_wheel_link">
    <inertial>
      <origin xyz="0 0 0" rpy="0 0 0" />
      <mass value="0.1" />
      <inertia ixx="0.1" ixy="0" ixz="0" iyy="0.1" iyz="0" izz="0.1" />
    </inertial>

    <visual>
      <geometry>
        <cylinder length="0.02" radius="0.025" />
      </geometry>
      <material name="black">
        <color rgba="0 0 0 1" />
      </material>
    </visual>
  </link>

  <link name="right_front_wheel_link">
    <inertial>
      <origin xyz="0 0 0" rpy="0 0 0" />
      <mass value="0.1" />
      <inertia ixx="0.1" ixy="0" ixz="0" iyy="0.1" iyz="0" izz="0.1" />
    </inertial>

    <visual>
      <geometry>
        <cylinder length="0.02" radius="0.025" />
      </geometry>
      <material name="black">
        <color rgba="0 0 0 1" />
      </material>
    </visual> 0 <collision>
      <origin xyz="0 0 0" rpy="0 0 0" />
      <geometry>
        <cylinder length="0.02" radius="0.025" />
      </geometry>
    </collision>
  </link>

  <joint name="right_wheel_joint" type="continuous">
    <axis xyz="0 0 -1" />
    <parent link="base_link" />
    <child link="right_wheel_link" />
    <origin rpy="1.5707 0 0" xyz=" 0.1 -0.09 -0.03" />
  </joint>

  <joint name="right_front_wheel_joint" type="continuous">
    <axis xyz="0 0 -1" />
    <parent link="base_link" />
    <child link="right_front_wheel_link" />
    <origin rpy="1.5707 0 0" xyz=" -0.1 -0.09 -0.03" />
  </joint>

  <link name="left_wheel_link">
    <inertial>
      <origin xyz="0 0 0" rpy="0 0 0" />
      <mass value="0.1" />
      <inertia ixx="0.1" ixy="0" ixz="0" iyy="0.1" iyz="0" izz="0.1" />
    </inertial>

    <visual>
      <geometry>
        <cylinder length="0.02" radius="0.025" />
      </geometry>
      <material name="black">
        <color rgba="0 0 0 1" />
      </material>
    </visual>

    <collision>
      <origin xyz="0 0 0" rpy="0 0 0" />
      <geometry>
        <cylinder length="0.02" radius="0.025" />
      </geometry>
    </collision>
  </link>

  <link name="left_front_wheel_link">
    <inertial>
      <origin xyz="0 0 0" rpy="0 0 0" />
      <mass value="0.1" />
      <inertia ixx="0.1" ixy="0" ixz="0" iyy="0.1" iyz="0" izz="0.1" />
    </inertial>

    <visual>
      <geometry>
        <cylinder length="0.02" radius="0.025" />
      </geometry>
      <material name="black">
        <color rgba="0 0 0 1" />
      </material>
    </visual>

    <collision>
      <origin xyz="0 0 0" rpy="0 0 0" />
      <geometry>
        <cylinder length="0.02" radius="0.025" />
      </geometry>
    </collision>
  </link>

  <joint name="left_wheel_joint" type="continuous">
    <axis xyz="0 0 -1" />
    <parent link="base_link" />
    <child link="left_wheel_link" />
    <origin rpy="1.5707 0 0" xyz="0.1 0.09 -0.03" />
  </joint>

  <joint name="left_front_wheel_joint" type="continuous">
    <axis xyz="0 0 -1" />
    <parent link="base_link" />
    <child link="left_front_wheel_link" />
    <origin rpy="1.5707 0 0" xyz="-0.1 0.09 -0.03" />
  </joint>

  <!-- imu sensor -->
  <link name="imu">
    <visual>
      <geometry>
        <box size="0.01 0.01 0.01" />
      </geometry>
      <material name="white">
        <color rgba="1 1 1 1 " />
      </material>
    </visual>
  </link>

  <joint name="imu_joint" type="fixed">
    <parent link="base_link" />
    <child link="imu" />
    <origin xyz="0.08 0 0.025" />
  </joint>

</robot>
