<?xml version="1.0"?>
<robot name="mybot" xmlns:xacro="http://ros.org/wiki/xacro" >

  <xacro:include filename="$(find realsense2_description)/urdf/_d455.urdf.xacro" />
  <xacro:include filename="$(find umbot)/urdf/mybot.gazebo.xacro" />

  <link name="base_footprint" />

  <joint name="base_link_footprint" type="fixed">
    <axis xyz="0 0 0" />
    <parent link="base_footprint" />
    <child link="base_link" />
    <origin rpy="0 0 0" xyz=" 0 0 0" />
  </joint>


  <link name="base_link">
    <inertial>
      <origin xyz="0 0 0" rpy="0 0 0" />
      <mass value="10" />
      <inertia ixx="0.1" ixy="0" ixz="0" iyy="0.1" iyz="0" izz="0.1" />
    </inertial>

    <visual>
      <geometry>
        <box size="0.25 0.16 0.05" />
      </geometry>
      <origin rpy="0 0 0" xyz="0 0 0" />
      <material name="blue">
        <color rgba="0 0 0.8 1" />
      </material>
    </visual>

    <collision>
      <origin xyz="0 0 0" rpy="0 0 0" />
      <geometry>
        <box size="0.25 0.16 0.05" />
      </geometry>
    </collision>

  </link>


  <link name="right_wheel_link">
    <inertial>
      <origin xyz="0 0 0" rpy="0 0 0" />
      <mass value="0.1" />
      <inertia ixx="0.1" ixy="0" ixz="0" iyy="0.1" iyz="0" izz="0.1" />
    </inertial>

    <visual>
      <geometry>
        <cylinder length="0.02" radius="0.025" />
      </geometry>
      <material name="black">
        <color rgba="0 0 0 1" />
      </material>
    </visual>
  </link>

  <link name="right_front_wheel_link">
    <inertial>
      <origin xyz="0 0 0" rpy="0 0 0" />
      <mass value="0.1" />
      <inertia ixx="0.1" ixy="0" ixz="0" iyy="0.1" iyz="0" izz="0.1" />
    </inertial>

    <visual>
      <geometry>
        <cylinder length="0.02" radius="0.025" />
      </geometry>
      <material name="black">
        <color rgba="0 0 0 1" />
      </material>
    </visual>

    <collision>
      <origin xyz="0 0 0" rpy="0 0 0" />
      <geometry>
        <cylinder length="0.02" radius="0.025" />
      </geometry>
    </collision>
  </link>

  <joint name="right_wheel_joint" type="continuous">
    <axis xyz="0 0 -1" />
    <parent link="base_link" />
    <child link="right_wheel_link" />
    <origin rpy="1.5707 0 0" xyz=" 0.1 -0.09 -0.03" />
  </joint>

  <joint name="right_front_wheel_joint" type="continuous">
    <axis xyz="0 0 -1" />
    <parent link="base_link" />
    <child link="right_front_wheel_link" />
    <origin rpy="1.5707 0 0" xyz=" -0.1 -0.09 -0.03" />
  </joint>

  <link name="left_wheel_link">
    <inertial>
      <origin xyz="0 0 0" rpy="0 0 0" />
      <mass value="0.1" />
      <inertia ixx="0.1" ixy="0" ixz="0" iyy="0.1" iyz="0" izz="0.1" />
    </inertial>

    <visual>
      <geometry>
        <cylinder length="0.02" radius="0.025" />
      </geometry>
      <material name="black">
        <color rgba="0 0 0 1" />
      </material>
    </visual>

    <collision>
      <origin xyz="0 0 0" rpy="0 0 0" />
      <geometry>
        <cylinder length="0.02" radius="0.025" />
      </geometry>
    </collision>
  </link>

  <link name="left_front_wheel_link">
    <inertial>
      <origin xyz="0 0 0" rpy="0 0 0" />
      <mass value="0.1" />
      <inertia ixx="0.1" ixy="0" ixz="0" iyy="0.1" iyz="0" izz="0.1" />
    </inertial>

    <visual>
      <geometry>
        <cylinder length="0.02" radius="0.025" />
      </geometry>
      <material name="black">
        <color rgba="0 0 0 1" />
      </material>
    </visual>

    <collision>
      <origin xyz="0 0 0" rpy="0 0 0" />
      <geometry>
        <cylinder length="0.02" radius="0.025" />
      </geometry>
    </collision>
  </link>

  <joint name="left_wheel_joint" type="continuous">
    <axis xyz="0 0 -1" />
    <parent link="base_link" />
    <child link="left_wheel_link" />
    <origin rpy="1.5707 0 0" xyz="0.1 0.09 -0.03" />
  </joint>

  <joint name="left_front_wheel_joint" type="continuous">
    <axis xyz="0 0 -1" />
    <parent link="base_link" />
    <child link="left_front_wheel_link" />
    <origin rpy="1.5707 0 0" xyz="-0.1 0.09 -0.03" />
  </joint>

  <!-- imu sensor -->
  <link name="imu">
    <visual>
      <geometry>
        <box size="0.01 0.01 0.01" />
      </geometry>
      <material name="white">
        <color rgba="1 1 1 1 " />
      </material>
    </visual>
  </link>

  <joint name="imu_joint" type="fixed">
    <parent link="base_link" />
    <child link="imu" />
    <origin xyz="0.08 0 0.025" />
  </joint>




  <xacro:arg name="use_nominal_extrinsics" default="false" />
  <xacro:arg name="add_plug" default="false" />
  <xacro:arg name="use_mesh" default="true" />
  <xacro:arg name="name" default="camera" />
  <xacro:arg name="topics_ns" default="camera" />
  <xacro:arg name="publish_pointcloud" default="true" />
  <xacro:include filename="$(find realsense2_description)/urdf/_d435.urdf.xacro" />
  <xacro:sensor_d435 parent="base_link" use_nominal_extrinsics="$(arg use_nominal_extrinsics)"
    add_plug="$(arg add_plug)" use_mesh="$(arg use_mesh)" name="$(arg name)"
    topics_ns="$(arg topics_ns)" publish_pointcloud="$(arg publish_pointcloud)">
  <origin xyz="0.1 0 0.025" rpy="0 0 0" />
</xacro:sensor_d435>

<link name="laser_livox">
  <xacro:null_inertial/>
  <visual> 
    <origin xyz="0.00 0 0.0" rpy="0 0 0"/>
    <geometry>
      <mesh filename="package://livox_laser_simulation/meshes/livox_mid40.dae">
      </mesh>
    </geometry>
  </visual>

  <collision>
    <origin xyz="0 0 0" rpy="0 0 0" />
    <geometry> 
      <mesh filename="package://livox_laser_simulation/meshes/livox_mid40.dae"/> 
    </geometry>
  </collision>
</link>

<joint name="$livox_to_base_joint" type="fixed">
  <parent link="base_link"/>
  <child link="laser_livox"/>
  <origin rpy="0 0 0" xyz="0.0 0.0 0.05"/>
</joint>


  </robot>
